Workbook
Name _Hlk470452949: Report!#REF!
Name _Hlk470701027: Report!$A$17
Name _Hlk470701162: Report!$A$39

Sheet Report
A1: Quality Inspection & Test Report V4.8
A3: Yeatru Sourcing
A4: Standard: | C4: ANSI/ASQC Z1.4-2003 | F4: Level : | I4: AQL Level II
A5: Inspection Type: | C5: Final Random Inspection (FRI) | F5: Inspected By: | I5: Yeatru Sourcing QC
A6: Factory Name: | C6: Shaoxing Lvyinghong Houseware Co., Ltd. | F6: Vendor Type: | I6: Factory
A7: Factory Location: | C7: Lianzhong Village, Xialv Town, Keqiao District, Shaoxing，ZHEJIANG ,CHINA | F7: Date: | I7: 2026-10-14
A8: P.O. #: | C8: DF260812 | F8: Product Description | I8: CHESYPORA Premium Microfiber Entrance Mat, 60 × 90 cm (Model PC0010; Amazon FNSKU: X002NV3RHP)
A9: P.O. Quantity: | C9: =D63+F63+H63+J63+L63+D86+F86+H86+J86+L86+D109+F109+H109+J109+L109+D132+F132+H132+J132+L132 -> 500 | F9: P.O. Cartons: | I9: =I39+I40+I41+I42+I43+I44+I45+I46+I47+I48+I49+I50+I51+I52+I53+I54+I55+I56+I57+I58 -> 42
A10: Completed% | C10: 100% (bulk packed, 42 cartons ready) | F10: Customer Name: | I10: SHOPCORTIZ LLC
A11: Spelling Check: | C11: Checked – 1 artwork text error found (see Remark 4) | F11: Drop/Impact Testing | I11: Untested
A12: Overall Inspection Result: | E12: NOT PASSED – PENDING
A14: SKU# Measurement | E14: Product | H14: Package | K14: Weight/pcs (kg) | M14: Pack size
E15: Length | F15: Width | G15: Height | H15: Length | I15: Width | J15: Height
E16: (cm) | F16: (cm) | G16: (cm) | H16: (cm) | I16: (cm) | J16: (cm)
A17: 1 | B17: PC0010 | E17: 60 | F17: 90 | G17: 0.9–1.0 | H17: 62 | I17: 13 | J17: 13 | K17: 0.763–1.102 | M17: 12 pcs/ctn
A18: 2
A19: 3
A20: 4
A21: 5
A22: 6
A23: 7
A24: 8
A25: 9
A26: 10
A27: 11
A28: 12
A29: 13
... A36: 20
A38: Carton Measurement | E38: Length (cm) | F38: Width (cm) | G38: Height (cm) | H38: Pcs/ctns | I38: CTNS | J38: G.W/CTNS | K38: TOTAL CBM | L38: TOTAL GW
A39: 1 | B39: =B17 -> PC0010 | E39: 51 | F39: 41 | G39: 65.5 | H39: 12 | I39: 42 | J39: 21.64 | K39: =E39*F39*G39*I39/1000000 -> 5.752341 | L39: =I39*J39 -> 908.88
A40: 2 | B40: =B18 -> 0 | K40: =E40*F40*G40*I40/1000000 -> 0 | L40: =I40*J40 -> 0
A41: 3 | B41: =B19 -> 0 | K41: =E41*F41*G41*I41/1000000 -> 0 | L41: =I41*J41 -> 0
A42: 4 | B42: =B20 -> 0 | K42: =E42*F42*G42*I42/1000000 -> 0 | L42: =I42*J42 -> 0
A43: 5 | B43: =B21 -> 0 | K43: =E43*F43*G43*I43/1000000 -> 0 | L43: =I43*J43 -> 0
A44: 6 | B44: =B22 -> 0 | K44: =E44*F44*G44*I44/1000000 -> 0 | L44: =I44*J44 -> 0
A45: 7 | B45: =B23 -> 0 | K45: =E45*F45*G45*I45/1000000 -> 0 | L45: =I45*J45 -> 0
A46: 8 | B46: =B24 -> 0 | K46: =E46*F46*G46*I46/1000000 -> 0 | L46: =I46*J46 -> 0
A47: 9 | B47: =B25 -> 0 | K47: =E47*F47*G47*I47/1000000 -> 0 | L47: =I47*J47 -> 0
A48: 10 | B48: =B26 -> 0 | K48: =E48*F48*G48*I48/1000000 -> 0 | L48: =I48*J48 -> 0
A49: 11 | B49: =B27 -> 0 | K49: =E49*F49*G49*I49/1000000 -> 0 | L49: =I49*J49 -> 0
...

Sheet Photos 1 - Site & Sampling
B1: PHOTOS 1 — FACTORY, BULK QUANTITY & SAMPLING (all photos taken on site, 2026-10-14)
B2: CHESYPORA Premium Microfiber Entrance Mat 60 × 90 cm (PC0010 / FNSKU X002NV3RHP) | Inspection date: 2026-10-14 | Page reference of the main QC report
B4: 1. Factory entrance & production
B5: 1. Factory entrance | H5: 2. Production line in operation
B7: 3. Production / packing area – WIP | H7: 4. On-site dimension check of each sampled unit (tape measure)
B10: 2. Finished bulk goods — 42 cartons
B11: 5. Bulk stock in warehouse: 42 master cartons (view 1) | H11: 6. Bulk stock in warehouse: 42 master cartons (view 2)
B13: 7. Packed hexagonal boxes, polybags and materials at factory after inspection | H13: 8. Reference sample prepared by the factory
B17: 3. Sampling
B18: 9. Seven cartons sampled from different stacking positions (square-root method, √42 ≈ 7)
B20: Sampling plan: 7 of 42 cartons (square-root method) drawn from different stacking positions; 50 pcs taken from the sampled cartons and each unit measured, weighed and inspected one by one (AQL Level II, sample size 50). The last carton of the lot is a remainder carton; no remainder marking was found on any carton.

Sheet Photos 2 - Pack & Packaging
B1: PHOTOS 2 — MASTER CARTON, HEXAGONAL BOX, POLYBAG, LABELS & BELLY BAND
B2: CHESYPORA Premium Microfiber Entrance Mat 60 × 90 cm (PC0010 / FNSKU X002NV3RHP) | Inspection date: 2026-10-14 | Page reference of the main QC report
B4: 4. Master carton — marks, weighing & measuring
B5: 10. Shipping mark: QTY / G.W. / N.W. fields BLANK; printed MEAS 51×41×64 cm (actual 65.5 cm); 'Heavy Package' label applied | H5: 11. Master carton – side without shipping mark
B7: 12. Master carton – general outlook | H7: 13. Carton gross weight check (reading 21.684 kg; range of 7 cartons 21.260–21.815 kg)
B9: 14. Carton length measured 51 cm | H9: 15. Carton width measured 41 cm
B11: 16. Carton height measured 65.5 cm | H11: 17. Inside master carton: 12 hexagonal boxes (4 × 3) with cardboard divider
B14: 5. Unit hexagonal gift box
B15: 18. Unit hexagonal gift box – full outlook (60 × 90 cm, pile 0.9–1.0 cm printed) | H15: 19. Separate slip-on lid – lid is NOT glued to the base and separates when the unit is lifted (FBA risk)
B17: 20. Unit box – alternative view | H17: 21. Box flat-to-flat width measured
B19: 22. Hexagon point-to-point measured ≈ 12.5–13 cm | H19: 23. Hexagonal end measured
B21: 24. Inside of empty hexagonal box | H21: 25. Unit box – general outlook
B24: 6. Polybag, card, belly band & labels
B25: 26. Rolled mat in polybag with French suffocation warning – note spacing error in “D'étouffement” (printed “D' etouffement”) | H25: 27. Unit as packed: polybag, belly band, welcome card and care label
B27: 28. Polybag packaging check | H27: 29. Welcome / thank-you card (“Bienvenue chez CHESYPORA”)
B29: 30. Belly band artwork: CHESYPORA Entrance Mat, 60 × 90 cm, pile 0.9–1.0 cm | H29: 31. Belly band loosens after roll diameter shrinkage – part of the text is covered
B31: 32. Woven brand label & care label: 100% polyester microfibre, 100% TPR base; PC0010; LOT 20260730 | H31: 33. Brand / care label check

Sheet Photos 3 - Tests & Measures
B1: PHOTOS 3 — SAMPLE COMPARISON, DIMENSIONS, WEIGHT & ON-SITE TESTS
B2: CHESYPORA Premium Microfiber Entrance Mat 60 × 90 cm (PC0010 / FNSKU X002NV3RHP) | Inspection date: 2026-10-14 | Page reference of the main QC report
B4: 7. Approved sample vs mass production
B5: 34. Approved sample (top) vs mass product (bottom) – overall appearance matches | H5: 35. Sample vs mass product – face yarn / colour comparison
B7: 36. Sample vs mass product – edge binding comparison | H7: 37. Sample vs mass product – overall comparison (view 2)
B10: 8. Dimensions & pile height (50 units measured individually)
B11: 38. Pile height measured ≈ 1 cm (specification 0.9–1.0 cm) | H11: 39. Mass-product dimension measurement (60 × 90 cm, tolerance ±1 cm)
B13: 40. Mass-product dimension measurement
B16: 9. Net weight check (product only)
B17: 41. Net weight 1,003.6 g | H17: 42. Net weight 870.0 g
B19: 43. Net weight 969.8 g | H19: 44. TPR anti-slip backing – thickness/weight inconsistent between units (range 763.4–1,102.0 g)
B22: 10. On-site tests
B23: 45. TUF BIND (TUFT WITHDRAWAL) TEST – FAILED: tufts can be pulled out under local tension (critical) | H23: 46. Tuft withdrawal test – tuft pulling at edge
B25: 47. Tuft withdrawal test – tuft cluster pulling out
H26: SLIP-RESISTANCE (FRICTION) TEST – PASSED. Method: mat laid on a smooth table surface; the mat grips the surface and is hard to push by hand (see video clip “Slip Resistance Test.mp4”). VIDEO CLIPS AVAILABLE ON REQUEST: “19-Tuft withdrawal test (1).mp4” (failed test), “Slip Resistance Test.mp4” (passed test), “sampled and open carton.mp4”, “2-Production line (2)/(7).mp4”.

Sheet Photos 4 - Defects & Findings
B1: PHOTOS 4 — DEFECTS, PACKAGING RISK & MARKING FINDINGS
B2: CHESYPORA Premium Microfiber Entrance Mat 60 × 90 cm (PC0010 / FNSKU X002NV3RHP) | Inspection date: 2026-10-14 | Page reference of the main QC report
B4: 11. Critical finding — tuft bind test failed
B5: 48. Tuft bind test FAILED – tufts pull out under local tension; withdrawal not severe, practical risk to the end user limited (critical-grade)
B8: 12. Defects on gift boxes (spare boxes confirmed available at factory)
B9: 49. MAJOR – wrinkle on hexagonal box, 1 pc | H9: 50. MINOR – wrinkle on hexagonal box, 1 pc
B11: 51. MINOR – colour shade difference between box lid and base, 1 pc
B14: 13. Defect on mat
B15: 52. MINOR – one loose thread < 0.5 cm on backing edge; trimmed / repaired on site
B18: 14. Systemic marking / artwork findings
B19: 53. Master-carton QTY / G.W. / N.W. left blank – to be filled before shipment | H19: 54. Polybag warning text – extra space in “D'étouffement” – artwork correction required
B21: 55. Belly-band text partly covered after diameter shrinkage – trim excess or resize
B24: 15. Packaging risk for Amazon FBA
B25: 56. Hexagonal box lid not glued to the base – lid comes off first when units are taken out of the master carton | H25: 57. Hexagonal box structure unstable – high FBA last-mile crushing risk; glue/secure the lid or add transit protection

Sheet Measurement Data
B1: Measurement & Weight Records – 50 sampled units (all units measured & weighed individually) | H1: Sampled master cartons (7 of 42)
B3: Sample No. | C3: Width (cm) | D3: Length (cm) | E3: Pile height (cm) | F3: Net weight (g) | H3: Carton No. | I3: G.W. (kg) | J3: L×W×H (cm) | K3: CBM (m³) | L3: Pcs/ctn
B4: 1 | C4: 60 | D4: 59.8 | E4: 1 | F4: 998.8 | H4: 1 | I4: 21.26 | J4: 51 × 41 × 65.5 | K4: =51*41*65.5/1000000 -> 0.1369605 | L4: 12
B5: 2 | C5: 60 | D5: 89.6 | E5: 1 | F5: 1044.6 | H5: 2 | I5: 21.575 | J5: 51 × 41 × 65.5 | K5: =51*41*65.5/1000000 -> 0.1369605 | L5: 12
B6: 3 | C6: 60 | D6: 90 | E6: 1 | F6: 982 | H6: 3 | I6: 21.815 | J6: 51 × 41 × 65.5 | K6: =51*41*65.5/1000000 -> 0.1369605 | L6: 12
B7: 4 | C7: 60.2 | D7: 89.7 | E7: 1 | F7: 990 | H7: 4 | I7: 21.725 | J7: 51 × 41 × 65.5 | K7: =51*41*65.5/1000000 -> 0.1369605 | L7: 12
B8: 5 | C8: 60.4 | D8: 89.5 | E8: 1 | F8: 1018 | H8: 5 | I8: 21.815 | J8: 51 × 41 × 65.5 | K8: =51*41*65.5/1000000 -> 0.1369605 | L8: 12
B9: 6 | C9: 60.2 | D9: 89.8 | E9: 1 | F9: 1059 | H9: 6 | I9: 21.535 | J9: 51 × 41 × 65.5 | K9: =51*41*65.5/1000000 -> 0.1369605 | L9: 12
B10: 7 | C10: 59.9 | D10: 90.1 | E10: 1 | F10: 1001.2 | H10: 7 | I10: 21.76 | J10: 51 × 41 × 65.5 | K10: =51*41*65.5/1000000 -> 0.1369605 | L10: 12
B11: 8 | C11: 60.2 | D11: 90 | E11: 1 | F11: 1000.4
B12: 9 | C12: 60 | D12: 89.8 | E12: 1 | F12: 987.8 | H12: Average G.W. (kg) | I12: =AVERAGE(I4:I10) -> 21.640714 | J12: Total CBM (42 ctns) | L12: =AVERAGE(K4:K10)*42 -> 5.752341
B13: 10 | C13: 60 | D13: 90.7 | E13: 1 | F13: 996 | H13: Total (42 ctns) G.W. (kg) | I13: =AVERAGE(I4:I10)*42 -> 908.91
B14: 11 | C14: 60.4 | D14: 89.3 | E14: 1 | F14: 947.6
B15: 12 | C15: 60 | D15: 90 | E15: 1 | F15: 969.8
B16: 13 | C16: 60.8 | D16: 89.3 | E16: 1 | F16: 1086.2 | H16: FNSKU / barcode verification (electronic scan log)
B17: 14 | C17: 59.8 | D17: 90.6 | E17: 1 | F17: 1067.6 | H17: Barcode type | I17: Code 128 (FNSKU)
B18: 15 | C18: 60 | D18: 90.2 | E18: 1 | F18: 869.8 | H18: Scan content | I18: X002NV3RHP
B19: 16 | C19: 60 | D19: 90.2 | E19: 1 | F19: 1074.4 | H19: Units scanned | I19: 50
B20: 17 | C20: 59.8 | D20: 89.6 | E20: 1 | F20: 1031.6 | H20: Passed / Failed | I20: 50 passed / 0 failed
B21: 18 | C21: 60.5 | D21: 89.5 | E21: 1 | F21: 1035.8 | H21: First – last scan | I21: 2026-10-14 13:47:47 – 13:52:15
B22: 19 | C22: 60.2 | D22: 89.2 | E22: 1 | F22: 1041
B23: 20 | C23: 59.6 | D23: 90.8 | E23: 1 | F23: 1048
B24: 21 | C24: 60.2 | D24: 89.7 | E24: 1 | F24: 956.4
B25: 22 | C25: 60.4 | D25: 89.7 | E25: 1 | F25: 1015.2
B26: 23 | C26: 60.2 | D26: 89.5 | E26: 1 | F26: 981
B27: 24 | C27: 60 | D27: 90 | E27: 1 | F27: 990
B28: 25 | C28: 60 | D28: 90.5 | E28: 1 | F28: 991.8
B29: 26 | C29: 60.1 | D29: 89.3 | E29: 1 | F29: 1007.2
B30: 27 | C30: 61.5 | D30: 89.8 | E30: 1 | F30: 1072.4
B31: 28 | C31: 60.4 | D31: 89.7 | E31: 1 | F31: 959.6
B32: 29 | C32: 60.2 | D32: 89.6 | E32: 1 | F32: 987
B33: 30 | C33: 60.4 | D33: 90.5 | E33: 1 | F33: 963.4
... B53: 50 | C53: 60.5 | D53: 89.6 | E53: 1 | F53: 883.8
B54: Statistical summary
B55: Specification | C55: 60 ± 1 | D55: 90 ± 1 | E55: 0.9–1.0 | F55: —
B56: Minimum | C56: =MIN(C4:C53) -> 59.6 | D56: =MIN(D4:D53) -> 59.8 | E56: =MIN(E4:E53) -> 1 | F56: =MIN(F4:F53) -> 763.4
B57: Maximum | C57: =MAX(C4:C53) -> 61.5 | D57: =MAX(D4:D53) -> 90.8 | E57: =MAX(E4:E53) -> 1 | F57: =MAX(F4:F53) -> 1102
B58: Average | C58: =AVERAGE(C4:C53) -> 60.17 | D58: =AVERAGE(D4:D53) -> 89.204 | E58: =AVERAGE(E4:E53) -> 1 | F58: =AVERAGE(F4:F53) -> 997.328
B59: Std. deviation | C59: =STDEV(C4:C53) -> 0.3124949 | D59: =STDEV(D4:D53) -> 4.2629376 | E59: =STDEV(E4:E53) -> 0 | F59: =STDEV(F4:F53) -> 59.81888
B60: Range (max–min) | C60: =MAX(C4:C53)-MIN(C4:C53) -> 1.9 | D60: =MAX(D4:D53)-MIN(D4:D53) -> 31 | E60: =MAX(E4:E53)-MIN(E4:E53) -> 0 | F60: =MAX(F4:F53)-MIN(F4:F53) -> 338.6
...

Sheet Defect-En
A1: Defects Description
A2: OPP 袋装 | B2: 袋子有破损 | C2: Poly bag broken
B3: 袋子没有封好 | C3: Poly bag unsealed
B4: 袋量不一样 | C4: Pack size differences
B5: 无OPP袋 | C5: Poly bag lacking
B6: 塑料袋开口超5英寸无相应警示标 | C6: Poly bag opening side wider than 5" without suffocation warning
B7: 塑料袋尺寸不合适（过小） | C7: Poly bag too small
B8: 塑料袋尺寸超过产品尺寸以外3'英寸 | C8: Poly bag not protrude more than 3" past dimensions of the product
B9: 内置OPP袋无孔 | C9: No air hole on inner poly bag
B10: 内置OPP袋有条码 | C10: Barcode label sticked on inner poly bag
B11: PE袋相应类别产品 （液体,粉末,服装,玩具,纸产品） | C11: Liquid, powder, apparel, toys & paper product not packed in PE bag
A12: Packaging盒装 | B12: 产品有商家Logo | C12: Vendor's logo printed on package box
B13: 盒子没封好 | C13: Package box unsealed
B14: 有短数 | C14: Pack size differences
B15: 包装易损 | C15: Package box not sturdy
B16: 无包装 | C16: Package box lacking
B17: 吸塑包装需要厂检 | C17: Blister package inspected in factory
B18: 混装 | C18: Products assorted
B19: 换彩盒 | C19: Package box re-work
B20: 吸塑包装破开 | C20: Blister shell broken
B21: 不过防摔测试 | C21: Drop test failed
B22: 汽泡膜包装尖角部分 | C22: Sharp point wrapped with bubble film
B23: 尖锐产品必须盒装 | C23: Sharp product packed in cardboard box
B24: 盒子无钉 | C24: Glued box
A25: Barcode | B25: 袋子无条码 | C25: Package bag without barcode label
B26: 袋子多个条码 | C26: Package with multiple barcode labels
B27: 条码破损 | C27: Barcode label torn
B28: 有工厂条码 | C28: Factory barcode existed
B29: 条码错误 | C29: Barcode incorrect
B30: 混条码 | C30: Barcode mixed
A31: Product quality | B31: 功能问题 | C31: Functional issue
B32: 有短数 | C32: Quantity short
B33: Listing不符 | C33: Listing unmatched
B34: 产品有脏/污渍 /汽泡 | C34: Dirt, stain or bubble
B35: 缺少配件 | C35: Accessories lacking
B36: 图片和产品有色差 | C36: Product color differences with image
B37: 有修补痕迹 | C37: Noticeable mark of repair
B38: 产品有刺，开裂，掉漆， | C38: Burr, crack or paint-shedding
B39: 产品露钉子 | C39: Nail exposed
A40: Moisture | B40: 湿度不达标 | C40: Humidity substandard
...

Sheet Option
A1: AQL Level | I1: AQL sampling
B2: Size | C2: Sample | D2: Critical | E2: Major | F2: Minor | I2: Size | J2: Sample | K2: Critical | L2: Major | M2: Minor
A3: 2 | B3: 3-9 | C3: 2 | D3: 0 | E3: 0 | F3: 0 | I3: 2-8 | J3: 2 | K3: 0 | L3: 0 | M3: 0
A4: 9 | B4: 10-16 | C4: 3 | D4: 0 | E4: 0 | F4: 0 | I4: 9-15 | J4: 3 | K4: 0 | L4: 0 | M4: 0
A5: 16 | B5: 17-26 | C5: 5 | D5: 0 | E5: 0 | F5: 0 | I5: 16-25 | J5: 5 | K5: 0 | L5: 0 | M5: 0
A6: 27 | B6: 27-51 | C6: 8 | D6: 0 | E6: 0 | F6: 0 | I6: 26-50 | J6: 8 | K6: 0 | L6: 0 | M6: 0
A7: 51 | B7: 52-91 | C7: 13 | D7: 0 | E7: 0 | F7: 1 | I7: 51-90 | J7: 13 | K7: 0 | L7: 0 | M7: 1
A8: 91 | B8: 92-151 | C8: 20 | D8: 0 | E8: 0 | F8: 2 | I8: 91-150 | J8: 20 | K8: 0 | L8: 0 | M8: 2
A9: 151 | B9: 152-281 | C9: 32 | D9: 0 | E9: 1 | F9: 3 | I9: 151-280 | J9: 32 | K9: 0 | L9: 1 | M9: 3
A10: 281 | B10: 282-501 | C10: 50 | D10: 0 | E10: 2 | F10: 5 | I10: 281-500 | J10: 50 | K10: 0 | L10: 2 | M10: 5
A11: 501 | B11: 502-1200 | C11: 80 | D11: 0 | E11: 3 | F11: 7 | I11: 501-1200 | J11: 80 | K11: 0 | L11: 3 | M11: 7
A12: 1201 | B12: 1202-3201 | C12: 125 | D12: 0 | E12: 5 | F12: 10 | I12: 1201-3200 | J12: 125 | K12: 0 | L12: 5 | M12: 10
A13: 3201 | B13: 3202-10001 | C13: 200 | D13: 0 | E13: 7 | F13: 14 | I13: 3201-10000 | J13: 200 | K13: 0 | L13: 7 | M13: 14
A14: 10001 | B14: 10002-35001 | C14: 315 | D14: 0 | E14: 10 | F14: 21 | I14: 10001-35000 | J14: 315 | K14: 0 | L14: 10 | M14: 21
A15: 35001 | B15: 35002-150001 | C15: 500 | D15: 0 | E15: 14 | F15: 21 | I15: 35001-150000 | J15: 500 | K15: 0 | L15: 14 | M15: 21
A16: 150001
