Workbook
Name _Hlk470452949: Report!#REF!
Name _Hlk470701027: Report!$B$17
Name _Hlk470701162: Report!$B$39

Sheet Report
B1: Quality Inspection & Test Report V4.8
B3: Yeatru Sourcing
B4: Standard: | D4: ANSI/ASQC Z1.4-2003 | G4: Level : | J4: AQL Level II
B5: Inspection Type: | D5: Factory QC | G5: Inspected By:
B6: Factory Name: | G6: Vendor Type: | J6: Factory
B7: Factory Location: | G7: Date:
B8: P.O. #: | G8: Product Description
B9: P.O. Quantity: | D9: =E63+G63+I63+K63+M63+E86+G86+I86+K86+M86+E109+G109+I109+K109+M109+E132+G132+I132+K132+M132 -> 500 | G9: P.O. Cartons: | J9: =J39+J40+J41+J42+J43+J44+J45+J46+J47+J48+J49+J50+J51+J52+J53+J54+J55+J56+J57+J58 -> 0
B10: Completed% | G10: Customer Name:
B11: Spelling Check: | D11: N/A | G11: Drop/Impact Testing | J11: Untested
B12: Overall Inspection Result: | F12: Passed
B14: SKU# Measurement | F14: Product | I14: Package | L14: Weight/pcs (lbs) | N14: Pack size
F15: Length | G15: Width | H15: Height | I15: Length | J15: Width | K15: Height
F16: (inch) | G16: (inch) | H16: (inch) | I16: (inch) | J16: (inch) | K16: (inch)
B17: 1 | C17: 865865856
B18: 2
B19: 3
B20: 4
B21: 5
B22: 6
B23: 7
B24: 8
B25: 9
B26: 10
B27: 11
B28: 12
B29: 13
... B36: 20
B38: Carton Measurement | F38: Length (cm) | G38: Width (cm) | H38: Height (cm) | I38: Pcs/ctns | J38: CTNS | K38: G.W/CTNS | L38: TOTAL CBM | M38: TOTAL GW
B39: 1 | C39: =C17 -> 865865856 | L39: =F39*G39*H39*J39/1000000 -> 0 | M39: =J39*K39 -> 0
B40: 2 | C40: =C18 -> 0 | L40: =F40*G40*H40*J40/1000000 -> 0 | M40: =J40*K40 -> 0
B41: 3 | C41: =C19 -> 0 | L41: =F41*G41*H41*J41/1000000 -> 0 | M41: =J41*K41 -> 0
B42: 4 | C42: =C20 -> 0 | L42: =F42*G42*H42*J42/1000000 -> 0 | M42: =J42*K42 -> 0
B43: 5 | C43: =C21 -> 0 | L43: =F43*G43*H43*J43/1000000 -> 0 | M43: =J43*K43 -> 0
B44: 6 | C44: =C22 -> 0 | L44: =F44*G44*H44*J44/1000000 -> 0 | M44: =J44*K44 -> 0
B45: 7 | C45: =C23 -> 0 | L45: =F45*G45*H45*J45/1000000 -> 0 | M45: =J45*K45 -> 0
B46: 8 | C46: =C24 -> 0 | L46: =F46*G46*H46*J46/1000000 -> 0 | M46: =J46*K46 -> 0
B47: 9 | C47: =C25 -> 0 | L47: =F47*G47*H47*J47/1000000 -> 0 | M47: =J47*K47 -> 0
B48: 10 | C48: =C26 -> 0 | L48: =F48*G48*H48*J48/1000000 -> 0 | M48: =J48*K48 -> 0
B49: 11 | C49: =C27 -> 0 | L49: =F49*G49*H49*J49/1000000 -> 0 | M49: =J49*K49 -> 0
...

Sheet Option
A1: AQL Level | I1: AQL sampling
B2: Size | C2: Sample | D2: Critical | E2: Major | F2: Minor | I2: Size | J2: Sample | K2: Critical | L2: Major | M2: Minor
A3: 2 | B3: 3-9 | C3: 2 | D3: 0 | E3: 0 | F3: 0 | I3: 2-8 | J3: 2 | K3: 0 | L3: 0 | M3: 0
A4: 9 | B4: 10-16 | C4: 3 | D4: 0 | E4: 0 | F4: 0 | I4: 9-15 | J4: 3 | K4: 0 | L4: 0 | M4: 0
A5: 16 | B5: 17-26 | C5: 5 | D5: 0 | E5: 0 | F5: 0 | I5: 16-25 | J5: 5 | K5: 0 | L5: 0 | M5: 0
A6: 27 | B6: 27-51 | C6: 8 | D6: 0 | E6: 0 | F6: 0 | I6: 26-50 | J6: 8 | K6: 0 | L6: 0 | M6: 0
A7: 51 | B7: 52-91 | C7: 13 | D7: 0 | E7: 0 | F7: 1 | I7: 51-90 | J7: 13 | K7: 0 | L7: 0 | M7: 1
A8: 91 | B8: 92-151 | C8: 20 | D8: 0 | E8: 0 | F8: 2 | I8: 91-150 | J8: 20 | K8: 0 | L8: 0 | M8: 2
A9: 151 | B9: 152-281 | C9: 32 | D9: 0 | E9: 1 | F9: 3 | I9: 151-280 | J9: 32 | K9: 0 | L9: 1 | M9: 3
A10: 281 | B10: 282-501 | C10: 50 | D10: 0 | E10: 2 | F10: 5 | I10: 281-500 | J10: 50 | K10: 0 | L10: 2 | M10: 5
A11: 501 | B11: 502-1200 | C11: 80 | D11: 0 | E11: 3 | F11: 7 | I11: 501-1200 | J11: 80 | K11: 0 | L11: 3 | M11: 7
A12: 1201 | B12: 1202-3201 | C12: 125 | D12: 0 | E12: 5 | F12: 10 | I12: 1201-3200 | J12: 125 | K12: 0 | L12: 5 | M12: 10
A13: 3201 | B13: 3202-10001 | C13: 200 | D13: 0 | E13: 7 | F13: 14 | I13: 3201-10000 | J13: 200 | K13: 0 | L13: 7 | M13: 14
A14: 10001 | B14: 10002-35001 | C14: 315 | D14: 0 | E14: 10 | F14: 21 | I14: 10001-35000 | J14: 315 | K14: 0 | L14: 10 | M14: 21
A15: 35001 | B15: 35002-150001 | C15: 500 | D15: 0 | E15: 14 | F15: 21 | I15: 35001-150000 | J15: 500 | K15: 0 | L15: 14 | M15: 21
A16: 150001

Sheet Defect-En
A1: Defects Description
A2: OPP 袋装 | B2: 袋子有破损 | C2: Poly bag broken
B3: 袋子没有封好 | C3: Poly bag unsealed
B4: 袋量不一样 | C4: Pack size differences
B5: 无OPP袋 | C5: Poly bag lacking
B6: 塑料袋开口超5英寸无相应警示标 | C6: Poly bag opening side wider than 5" without suffocation warning
B7: 塑料袋尺寸不合适（过小） | C7: Poly bag too small
B8: 塑料袋尺寸超过产品尺寸以外3'英寸 | C8: Poly bag not protrude more than 3" past dimensions of the product
B9: 内置OPP袋无孔 | C9: No air hole on inner poly bag
B10: 内置OPP袋有条码 | C10: Barcode label sticked on inner poly bag
B11: PE袋相应类别产品 （液体,粉末,服装,玩具,纸产品） | C11: Liquid, powder, apparel, toys & paper product not packed in PE bag
A12: Packaging盒装 | B12: 产品有商家Logo | C12: Vendor's logo printed on package box
B13: 盒子没封好 | C13: Package box unsealed
B14: 有短数 | C14: Pack size differences
B15: 包装易损 | C15: Package box not sturdy
B16: 无包装 | C16: Package box lacking
B17: 吸塑包装需要厂检 | C17: Blister package inspected in factory
B18: 混装 | C18: Products assorted
B19: 换彩盒 | C19: Package box re-work
B20: 吸塑包装破开 | C20: Blister shell broken
B21: 不过防摔测试 | C21: Drop test failed
B22: 汽泡膜包装尖角部分 | C22: Sharp point wrapped with bubble film
B23: 尖锐产品必须盒装 | C23: Sharp product packed in cardboard box
B24: 盒子无钉 | C24: Glued box
A25: Barcode | B25: 袋子无条码 | C25: Package bag without barcode label
B26: 袋子多个条码 | C26: Package with multiple barcode labels
B27: 条码破损 | C27: Barcode label torn
B28: 有工厂条码 | C28: Factory barcode existed
B29: 条码错误 | C29: Barcode incorrect
B30: 混条码 | C30: Barcode mixed
A31: Product quality | B31: 功能问题 | C31: Functional issue
B32: 有短数 | C32: Quantity short
B33: Listing不符 | C33: Listing unmatched
B34: 产品有脏/污渍 /汽泡 | C34: Dirt, stain or bubble
B35: 缺少配件 | C35: Accessories lacking
B36: 图片和产品有色差 | C36: Product color differences with image
B37: 有修补痕迹 | C37: Noticeable mark of repair
B38: 产品有刺，开裂，掉漆， | C38: Burr, crack or paint-shedding
B39: 产品露钉子 | C39: Nail exposed
A40: Moisture | B40: 湿度不达标 | C40: Humidity substandard
...
